multiprocessing.pool.RemoteTraceback: 
"""
Traceback (most recent call last):
  File "/home/zerui603/.conda/envs/PytorchCd11/lib/python3.7/multiprocessing/pool.py", line 121, in worker
    result = (True, func(*args, **kwds))
  File "/home/zerui603/.conda/envs/PytorchCd11/lib/python3.7/multiprocessing/pool.py", line 44, in mapstar
    return list(map(*args))
  File "/home/zerui603/MDN_lc_iden/iden_1D/eyetest.py", line 24, in plotandmove
    data_lc = np.load(path_data+str(index_list[index])+".npy",allow_pickle=True)
  File "/home/zerui603/.local/lib/python3.7/site-packages/numpy/lib/npyio.py", line 428, in load
    fid = open(os_fspath(file), "rb")
FileNotFoundError: [Errno 2] No such file or directory: '/scratch/zerui603/KMT_simu_lowratio/qseries/00to10/146672.npy'
"""

The above exception was the direct cause of the following exception:

Traceback (most recent call last):
  File "/home/zerui603/MDN_lc_iden/iden_1D/eyetest.py", line 68, in <module>
    p.map(plotandmove,range(500))
  File "/home/zerui603/.conda/envs/PytorchCd11/lib/python3.7/multiprocessing/pool.py", line 268, in map
    return self._map_async(func, iterable, mapstar, chunksize).get()
  File "/home/zerui603/.conda/envs/PytorchCd11/lib/python3.7/multiprocessing/pool.py", line 657, in get
    raise self._value
FileNotFoundError: [Errno 2] No such file or directory: '/scratch/zerui603/KMT_simu_lowratio/qseries/00to10/146672.npy'
